Workbook

Sheet 2025-2026 Tracker
A1: Date | B1: Type | C1: Category | D1: Subcategory | E1: Project | F1: Counterparty | G1: Description | H1: Amount (orig) | I1: Currency | J1: FX rate (to EUR) | K1: Amount (EUR) | L1: Payment method | M1: Status | N1: Paid by | O1: Reimbursement status | P1: Receipt / doc ref | Q1: Invoice # | R1: Notes | S1: Estimated?
A2: 45683 | B2: Expense | C2: Fixed costs | D2: Obsidian Publish | E2: ReFi BCN Website maintenance | F2: Obsidian | G2: Obsidian Publish subscription (monthly) | H2: 10 | I2: USD | J2: =IFERROR(__xludf.DUMMYFUNCTION("GOOGLEFINANCE(""CURRENCY:USDEUR"",,A2,A2)"),"#N/A") -> #N/A | K2: =IFERROR(H2*J2,"") | L2: Card | M2: Cleared | N2: Luiz personal | O2: To be reimbursed | R2: Amount paid: 10 USD (convert to EUR when known). Ongoing, not settled (reimbursement pending). | S2: No
A3: 45714 | B3: Expense | C3: Fixed costs | D3: Obsidian Publish | E3: ReFi BCN Website maintenance | F3: Obsidian | G3: Obsidian Publish subscription (monthly) | H3: 10 | I3: USD | J3: =IFERROR(__xludf.DUMMYFUNCTION("GOOGLEFINANCE(""CURRENCY:USDEUR"",A3)"),"#N/A") -> #N/A | K3: =IFERROR(H3*J3,"") | L3: Card | M3: Cleared | N3: Luiz personal | O3: To be reimbursed | R3: Amount paid: 10 USD (convert to EUR when known). Ongoing, not settled (reimbursement pending). | S3: No
A4: 45742 | B4: Expense | C4: Fixed costs | D4: Obsidian Publish | E4: ReFi BCN Website maintenance | F4: Obsidian | G4: Obsidian Publish subscription (monthly) | H4: 10 | I4: USD | J4: =IFERROR(__xludf.DUMMYFUNCTION("IFERROR(INDEX(GOOGLEFINANCE(""CURRENCY:USDEUR"",A4),2,2),"""")"),"") | K4: =IFERROR(H4*J4,"") -> 0 | L4: Card | M4: Cleared | N4: Luiz personal | O4: To be reimbursed | R4: Amount paid: 10 USD (convert to EUR when known). Ongoing, not settled (reimbursement pending). | S4: No
A5: 45752 | B5: Expense | C5: Fixed costs | D5: Obsidian Publish | E5: ReFi BCN Website maintenance | F5: Obsidian | G5: Obsidian Publish subscription (monthly – last before annual) | H5: 10 | I5: USD | J5: =IFERROR(__xludf.DUMMYFUNCTION("IFERROR(INDEX(GOOGLEFINANCE(""CURRENCY:USDEUR"",A5),2,2),"""")"),"") | K5: =IFERROR(H5*J5,"") -> 0 | L5: Card | M5: Cleared | N5: Luiz personal | O5: To be reimbursed | R5: Amount paid: 10 USD (convert to EUR when known). | S5: No
A6: 45792 | B6: Expense | C6: Fixed costs | D6: Obsidian Publish | E6: ReFi BCN Website maintenance | F6: Obsidian | G6: Obsidian Publish subscription (annual) | H6: 96 | I6: USD | J6: =IFERROR(__xludf.DUMMYFUNCTION("IFERROR(INDEX(GOOGLEFINANCE(""CURRENCY:USDEUR"",A6),2,2),"""")"),"") | K6: =IFERROR(H6*J6,"") -> 0 | L6: Card | M6: Cleared | N6: Luiz personal | O6: To be reimbursed | R6: Amount paid: 96 USD (annual). Ongoing, not settled (reimbursement pending). | S6: No
A7: 45714 | B7: Expense | C7: Fixed costs | D7: refibcn.cat domain | E7: ReFi BCN Website maintenance | F7: Domain registrar | G7: refibcn.cat domain renewal | H7: 45.68 | I7: EUR | J7: 1 | K7: 45.68 | L7: Card | M7: Cleared | N7: Luiz personal | O7: To be reimbursed | R7: Ongoing, not settled (reimbursement pending). | S7: No
A8: 45675 | B8: Expense | C8: Fixed costs | D8: Notion | E8: ReFi BCN Website maintenance | F8: Notion | G8: Notion subscription (monthly) | H8: 13.92 | I8: EUR | J8: 1 | K8: 13.92 | L8: Card | M8: Cleared | N8: Luiz personal | O8: To be reimbursed | R8: Ongoing, not settled (reimbursement pending). | S8: No
A9: 45706 | B9: Expense | C9: Fixed costs | D9: Notion | E9: ReFi BCN Website maintenance | F9: Notion | G9: Notion subscription (monthly) | H9: 13.92 | I9: EUR | J9: 1 | K9: 13.92 | L9: Card | M9: Cleared | N9: Luiz personal | O9: To be reimbursed | R9: Ongoing, not settled (reimbursement pending). | S9: No
A10: 45734 | B10: Expense | C10: Fixed costs | D10: Notion | E10: ReFi BCN Website maintenance | F10: Notion | G10: Notion subscription (monthly) | H10: 13.92 | I10: EUR | J10: 1 | K10: 13.92 | L10: Card | M10: Cleared | N10: Luiz personal | O10: To be reimbursed | R10: Ongoing, not settled (reimbursement pending). | S10: No
A11: 45765 | B11: Expense | C11: Fixed costs | D11: Notion | E11: ReFi BCN Website maintenance | F11: Notion | G11: Notion subscription (monthly) | H11: 13.92 | I11: EUR | J11: 1 | K11: 13.92 | L11: Card | M11: Cleared | N11: Luiz personal | O11: To be reimbursed | R11: Ongoing, not settled (reimbursement pending). | S11: No
A12: 45795 | B12: Expense | C12: Fixed costs | D12: Notion | E12: ReFi BCN Website maintenance | F12: Notion | G12: Notion subscription (monthly) | H12: 13.92 | I12: EUR | J12: 1 | K12: 13.92 | L12: Card | M12: Cleared | N12: Luiz personal | O12: To be reimbursed | R12: Ongoing, not settled (reimbursement pending). | S12: No
A13: 45826 | B13: Expense | C13: Fixed costs | D13: Notion | E13: ReFi BCN Website maintenance | F13: Notion | G13: Notion subscription (monthly) | H13: 13.92 | I13: EUR | J13: 1 | K13: 13.92 | L13: Card | M13: Cleared | N13: Luiz personal | O13: To be reimbursed | R13: Ongoing, not settled (reimbursement pending). | S13: No
A14: 45856 | B14: Expense | C14: Fixed costs | D14: Notion | E14: ReFi BCN Website maintenance | F14: Notion | G14: Notion subscription (monthly) | H14: 13.92 | I14: EUR | J14: 1 | K14: 13.92 | L14: Card | M14: Cleared | N14: Luiz personal | O14: To be reimbursed | R14: Ongoing, not settled (reimbursement pending). | S14: No
A15: 45887 | B15: Expense | C15: Fixed costs | D15: Notion | E15: ReFi BCN Website maintenance | F15: Notion | G15: Notion subscription (monthly) | H15: 13.92 | I15: EUR | J15: 1 | K15: 13.92 | L15: Card | M15: Cleared | N15: Luiz personal | O15: To be reimbursed | R15: Ongoing, not settled (reimbursement pending). | S15: No
A16: 45918 | B16: Expense | C16: Fixed costs | D16: Notion | E16: ReFi BCN Website maintenance | F16: Notion | G16: Notion subscription (monthly) | H16: 13.92 | I16: EUR | J16: 1 | K16: 13.92 | L16: Card | M16: Cleared | N16: Luiz personal | O16: To be reimbursed | R16: Ongoing, not settled (reimbursement pending). | S16: No
A17: 45948 | B17: Expense | C17: Fixed costs | D17: Notion | E17: ReFi BCN Website maintenance | F17: Notion | G17: Notion subscription (monthly) | H17: 13.92 | I17: EUR | J17: 1 | K17: 13.92 | L17: Card | M17: Cleared | N17: Luiz personal | O17: To be reimbursed | R17: Ongoing, not settled (reimbursement pending). | S17: No
A18: 45979 | B18: Expense | C18: Fixed costs | D18: Notion | E18: ReFi BCN Website maintenance | F18: Notion | G18: Notion subscription (monthly) | H18: 13.92 | I18: EUR | J18: 1 | K18: 13.92 | L18: Card | M18: Cleared | N18: Luiz personal | O18: To be reimbursed | R18: Ongoing, not settled (reimbursement pending). | S18: No
A19: 46009 | B19: Expense | C19: Fixed costs | D19: Notion | E19: ReFi BCN Website maintenance | F19: Notion | G19: Notion subscription (monthly) | H19: 13.92 | I19: EUR | J19: 1 | K19: 13.92 | L19: Card | M19: Cleared | N19: Luiz personal | O19: To be reimbursed | R19: Ongoing, not settled (reimbursement pending). | S19: No
A20: 46157 | B20: Expense | C20: Fixed costs | D20: Obsidian Publish | E20: ReFi BCN Website maintenance | F20: Obsidian | G20: Obsidian Publish subscription (annual renewal) | H20: 96 | I20: USD | J20: =IFERROR(__xludf.DUMMYFUNCTION("IFERROR(INDEX(GOOGLEFINANCE(""CURRENCY:USDEUR"",A20),2,2),"""")"),"") | K20: =IFERROR(H20*J20,"") -> 0 | L20: Card | M20: Expected | N20: Luiz personal | O20: To be reimbursed | R20: Expected: 96 USD (annual). Convert to EUR when known. | S20: Yes
A21: 46040 | B21: Expense | C21: Fixed costs | D21: Notion | E21: ReFi BCN Website maintenance | F21: Notion | G21: Notion subscription (monthly) | H21: 13.92 | I21: EUR | J21: 1 | K21: 13.92 | L21: Card | M21: Cleared | N21: Luiz personal | O21: To be reimbursed | R21: Ongoing, not settled (reimbursement pending). | S21: No
A22: 46071 | B22: Expense | C22: Fixed costs | D22: Notion | E22: ReFi BCN Website maintenance | F22: Notion | G22: Notion subscription (monthly) | H22: 13.92 | I22: EUR | J22: 1 | K22: 13.92 | L22: Card | M22: Expected | N22: Luiz personal | O22: To be reimbursed | R22: Ongoing, not settled (reimbursement pending). | S22: Yes
A23: 46099 | B23: Expense | C23: Fixed costs | D23: Notion | E23: ReFi BCN Website maintenance | F23: Notion | G23: Notion subscription (monthly) | H23: 13.92 | I23: EUR | J23: 1 | K23: 13.92 | L23: Card | M23: Expected | N23: Luiz personal | O23: To be reimbursed | R23: Ongoing, not settled (reimbursement pending). | S23: Yes
A24: 46130 | B24: Expense | C24: Fixed costs | D24: Notion | E24: ReFi BCN Website maintenance | F24: Notion | G24: Notion subscription (monthly) | H24: 13.92 | I24: EUR | J24: 1 | K24: 13.92 | L24: Card | M24: Expected | N24: Luiz personal | O24: To be reimbursed | R24: Ongoing, not settled (reimbursement pending). | S24: Yes
A25: 46160 | B25: Expense | C25: Fixed costs | D25: Notion | E25: ReFi BCN Website maintenance | F25: Notion | G25: Notion subscription (monthly) | H25: 13.92 | I25: EUR | J25: 1 | K25: 13.92 | L25: Card | M25: Expected | N25: Luiz personal | O25: To be reimbursed | R25: Ongoing, not settled (reimbursement pending). | S25: Yes
A26: 46191 | B26: Expense | C26: Fixed costs | D26: Notion | E26: ReFi BCN Website maintenance | F26: Notion | G26: Notion subscription (monthly) | H26: 13.92 | I26: EUR | J26: 1 | K26: 13.92 | L26: Card | M26: Expected | N26: Luiz personal | O26: To be reimbursed | R26: Ongoing, not settled (reimbursement pending). | S26: Yes
A27: 46221 | B27: Expense | C27: Fixed costs | D27: Notion | E27: ReFi BCN Website maintenance | F27: Notion | G27: Notion subscription (monthly) | H27: 13.92 | I27: EUR | J27: 1 | K27: 13.92 | L27: Card | M27: Expected | N27: Luiz personal | O27: To be reimbursed | R27: Ongoing, not settled (reimbursement pending). | S27: Yes
A28: 46252 | B28: Expense | C28: Fixed costs | D28: Notion | E28: ReFi BCN Website maintenance | F28: Notion | G28: Notion subscription (monthly) | H28: 13.92 | I28: EUR | J28: 1 | K28: 13.92 | L28: Card | M28: Expected | N28: Luiz personal | O28: To be reimbursed | R28: Ongoing, not settled (reimbursement pending). | S28: Yes
A29: 46283 | B29: Expense | C29: Fixed costs | D29: Notion | E29: ReFi BCN Website maintenance | F29: Notion | G29: Notion subscription (monthly) | H29: 13.92 | I29: EUR | J29: 1 | K29: 13.92 | L29: Card | M29: Expected | N29: Luiz personal | O29: To be reimbursed | R29: Ongoing, not settled (reimbursement pending). | S29: Yes
A30: 46313 | B30: Expense | C30: Fixed costs | D30: Notion | E30: ReFi BCN Website maintenance | F30: Notion | G30: Notion subscription (monthly) | H30: 13.92 | I30: EUR | J30: 1 | K30: 13.92 | L30: Card | M30: Expected | N30: Luiz personal | O30: To be reimbursed | R30: Ongoing, not settled (reimbursement pending). | S30: Yes
A31: 46344 | B31: Expense | C31: Fixed costs | D31: Notion | E31: ReFi BCN Website maintenance | F31: Notion | G31: Notion subscription (monthly) | H31: 13.92 | I31: EUR | J31: 1 | K31: 13.92 | L31: Card | M31: Expected | N31: Luiz personal | O31: To be reimbursed | R31: Ongoing, not settled (reimbursement pending). | S31: Yes
A32: 46374 | B32: Expense | C32: Fixed costs | D32: Notion | E32: ReFi BCN Website maintenance | F32: Notion | G32: Notion subscription (monthly) | H32: 13.92 | I32: EUR | J32: 1 | K32: 13.92 | L32: Card | M32: Expected | N32: Luiz personal | O32: To be reimbursed | R32: Ongoing, not settled (reimbursement pending). | S32: Yes

Sheet 2025-2026 Cash Flow
A1: Cash Flow — 2025-2026
C2: Jan 25 | D2: Feb 25 | E2: Mar 25 | F2: Apr 25 | G2: May 25 | H2: Jun 25 | I2: Jul 25 | J2: Aug 25 | K2: Sep 25 | L2: Oct 25 | M2: Nov 25 | N2: Dec 25 | O2: Jan 26 | P2: Feb 26 | Q2: Mar 26 | R2: Apr 26 | S2: May 26 | T2: Jun 26 | U2: Jul 26 | V2: Aug 26 | W2: Sep 26 | X2: Oct 26 | Y2: Nov 26 | Z2: Dec 26 | AA2: Total
C3: 45658 | D3: 45689 | E3: 45717 | F3: 45748 | G3: 45778 | H3: 45809 | I3: 45839 | J3: 45870 | K3: 45901 | L3: 45931 | M3: 45962 | N3: 45992 | O3: 46023 | P3: 46054 | Q3: 46082 | R3: 46113 | S3: 46143 | T3: 46174 | U3: 46204 | V3: 46235 | W3: 46266 | X3: 46296 | Y3: 46327 | Z3: 46357
A4: Income | C4: =SUM(C5:C9) -> 0 | D4: =SUM(D5:D9) -> 0 | E4: =SUM(E5:E9) -> 0 | F4: =SUM(F5:F9) -> 0 | G4: =SUM(G5:G9) -> 0 | H4: =SUM(H5:H9) -> 0 | I4: =SUM(I5:I9) -> 0 | J4: =SUM(J5:J9) -> 0 | ... Z4: =SUM(Z5:Z9) -> 0 | AA4: =SUM(C4:Z4) -> 0
A5: Project payments | C5: =SUMIFS('2025-2026 Tracker'!$K$2:$K$5000,'2025-2026 Tracker'!$A$2:$A$5000,">="&C3,'2025-2026 Tracker'!$A$2:$A$5000,"<="&EOMONTH(C3,0),'2025-2026 Tracker'!$B$2:$B$5000,"Income",'2025-2026 Tracker'!$C$2:$C$5000,"Project payments") -> 0 | D5: =SUMIFS('2025-2026 Tracker'!$K$2:$K$5000,'2025-2026 Tracker'!$A$2:$A$5000,">="&D3,'2025-2026 Tracker'!$A$2:$A$5000,"<="&EOMONTH(D3,0),'2025-2026 Tracker'!$B$2:$B$5000,"Income",'2025-2026 Tracker'!$C$2:$C$5000,"Project payments") -> 0 | E5: =SUMIFS('2025-2026 Tracker'!$K$2:$K$5000,'2025-2026 Tracker'!$A$2:$A$5000,">="&E3,'2025-2026 Tracker'!$A$2:$A$5000,"<="&EOMONTH(E3,0),'2025-2026 Tracker'!$B$2:$B$5000,"Income",'2025-2026 Tracker'!$C$2:$C$5000,"Project payments") -> 0 | F5: =SUMIFS('2025-2026 Tracker'!$K$2:$K$5000,'2025-2026 Tracker'!$A$2:$A$5000,">="&F3,'2025-2026 Tracker'!$A$2:$A$5000,"<="&EOMONTH(F3,0),'2025-2026 Tracker'!$B$2:$B$5000,"Income",'2025-2026 Tracker'!$C$2:$C$5000,"Project payments") -> 0 | G5: =SUMIFS('2025-2026 Tracker'!$K$2:$K$5000,'2025-2026 Tracker'!$A$2:$A$5000,">="&G3,'2025-2026 Tracker'!$A$2:$A$5000,"<="&EOMONTH(G3,0),'2025-2026 Tracker'!$B$2:$B$5000,"Income",'2025-2026 Tracker'!$C$2:$C$5000,"Project payments") -> 0 | H5: =SUMIFS('2025-2026 Tracker'!$K$2:$K$5000,'2025-2026 Tracker'!$A$2:$A$5000,">="&H3,'2025-2026 Tracker'!$A$2:$A$5000,"<="&EOMONTH(H3,0),'2025-2026 Tracker'!$B$2:$B$5000,"Income",'2025-2026 Tracker'!$C$2:$C$5000,"Project payments") -> 0 | I5: =SUMIFS('2025-2026 Tracker'!$K$2:$K$5000,'2025-2026 Tracker'!$A$2:$A$5000,">="&I3,'2025-2026 Tracker'!$A$2:$A$5000,"<="&EOMONTH(I3,0),'2025-2026 Tracker'!$B$2:$B$5000,"Income",'2025-2026 Tracker'!$C$2:$C$5000,"Project payments") -> 0 | J5: =SUMIFS('2025-2026 Tracker'!$K$2:$K$5000,'2025-2026 Tracker'!$A$2:$A$5000,">="&J3,'2025-2026 Tracker'!$A$2:$A$5000,"<="&EOMONTH(J3,0),'2025-2026 Tracker'!$B$2:$B$5000,"Income",'2025-2026 Tracker'!$C$2:$C$5000,"Project payments") -> 0 | ... Z5: =SUMIFS('2025-2026 Tracker'!$K$2:$K$5000,'2025-2026 Tracker'!$A$2:$A$5000,">="&Z3,'2025-2026 Tracker'!$A$2:$A$5000,"<="&EOMONTH(Z3,0),'2025-2026 Tracker'!$B$2:$B$5000,"Income",'2025-2026 Tracker'!$C$2:$C$5000,"Project payments") -> 0 | AA5: =SUM(C5:Z5) -> 0
A6: Retainers | C6: =SUMIFS('2025-2026 Tracker'!$K$2:$K$5000,'2025-2026 Tracker'!$A$2:$A$5000,">="&C3,'2025-2026 Tracker'!$A$2:$A$5000,"<="&EOMONTH(C3,0),'2025-2026 Tracker'!$B$2:$B$5000,"Income",'2025-2026 Tracker'!$C$2:$C$5000,"Retainers") -> 0 | D6: =SUMIFS('2025-2026 Tracker'!$K$2:$K$5000,'2025-2026 Tracker'!$A$2:$A$5000,">="&D3,'2025-2026 Tracker'!$A$2:$A$5000,"<="&EOMONTH(D3,0),'2025-2026 Tracker'!$B$2:$B$5000,"Income",'2025-2026 Tracker'!$C$2:$C$5000,"Retainers") -> 0 | E6: =SUMIFS('2025-2026 Tracker'!$K$2:$K$5000,'2025-2026 Tracker'!$A$2:$A$5000,">="&E3,'2025-2026 Tracker'!$A$2:$A$5000,"<="&EOMONTH(E3,0),'2025-2026 Tracker'!$B$2:$B$5000,"Income",'2025-2026 Tracker'!$C$2:$C$5000,"Retainers") -> 0 | F6: =SUMIFS('2025-2026 Tracker'!$K$2:$K$5000,'2025-2026 Tracker'!$A$2:$A$5000,">="&F3,'2025-2026 Tracker'!$A$2:$A$5000,"<="&EOMONTH(F3,0),'2025-2026 Tracker'!$B$2:$B$5000,"Income",'2025-2026 Tracker'!$C$2:$C$5000,"Retainers") -> 0 | G6: =SUMIFS('2025-2026 Tracker'!$K$2:$K$5000,'2025-2026 Tracker'!$A$2:$A$5000,">="&G3,'2025-2026 Tracker'!$A$2:$A$5000,"<="&EOMONTH(G3,0),'2025-2026 Tracker'!$B$2:$B$5000,"Income",'2025-2026 Tracker'!$C$2:$C$5000,"Retainers") -> 0 | H6: =SUMIFS('2025-2026 Tracker'!$K$2:$K$5000,'2025-2026 Tracker'!$A$2:$A$5000,">="&H3,'2025-2026 Tracker'!$A$2:$A$5000,"<="&EOMONTH(H3,0),'2025-2026 Tracker'!$B$2:$B$5000,"Income",'2025-2026 Tracker'!$C$2:$C$5000,"Retainers") -> 0 | I6: =SUMIFS('2025-2026 Tracker'!$K$2:$K$5000,'2025-2026 Tracker'!$A$2:$A$5000,">="&I3,'2025-2026 Tracker'!$A$2:$A$5000,"<="&EOMONTH(I3,0),'2025-2026 Tracker'!$B$2:$B$5000,"Income",'2025-2026 Tracker'!$C$2:$C$5000,"Retainers") -> 0 | J6: =SUMIFS('2025-2026 Tracker'!$K$2:$K$5000,'2025-2026 Tracker'!$A$2:$A$5000,">="&J3,'2025-2026 Tracker'!$A$2:$A$5000,"<="&EOMONTH(J3,0),'2025-2026 Tracker'!$B$2:$B$5000,"Income",'2025-2026 Tracker'!$C$2:$C$5000,"Retainers") -> 0 | ... Z6: =SUMIFS('2025-2026 Tracker'!$K$2:$K$5000,'2025-2026 Tracker'!$A$2:$A$5000,">="&Z3,'2025-2026 Tracker'!$A$2:$A$5000,"<="&EOMONTH(Z3,0),'2025-2026 Tracker'!$B$2:$B$5000,"Income",'2025-2026 Tracker'!$C$2:$C$5000,"Retainers") -> 0 | AA6: =SUM(C6:Z6) -> 0
A7: Grants | C7: =SUMIFS('2025-2026 Tracker'!$K$2:$K$5000,'2025-2026 Tracker'!$A$2:$A$5000,">="&C3,'2025-2026 Tracker'!$A$2:$A$5000,"<="&EOMONTH(C3,0),'2025-2026 Tracker'!$B$2:$B$5000,"Income",'2025-2026 Tracker'!$C$2:$C$5000,"Grants") -> 0 | D7: =SUMIFS('2025-2026 Tracker'!$K$2:$K$5000,'2025-2026 Tracker'!$A$2:$A$5000,">="&D3,'2025-2026 Tracker'!$A$2:$A$5000,"<="&EOMONTH(D3,0),'2025-2026 Tracker'!$B$2:$B$5000,"Income",'2025-2026 Tracker'!$C$2:$C$5000,"Grants") -> 0 | E7: =SUMIFS('2025-2026 Tracker'!$K$2:$K$5000,'2025-2026 Tracker'!$A$2:$A$5000,">="&E3,'2025-2026 Tracker'!$A$2:$A$5000,"<="&EOMONTH(E3,0),'2025-2026 Tracker'!$B$2:$B$5000,"Income",'2025-2026 Tracker'!$C$2:$C$5000,"Grants") -> 0 | F7: =SUMIFS('2025-2026 Tracker'!$K$2:$K$5000,'2025-2026 Tracker'!$A$2:$A$5000,">="&F3,'2025-2026 Tracker'!$A$2:$A$5000,"<="&EOMONTH(F3,0),'2025-2026 Tracker'!$B$2:$B$5000,"Income",'2025-2026 Tracker'!$C$2:$C$5000,"Grants") -> 0 | G7: =SUMIFS('2025-2026 Tracker'!$K$2:$K$5000,'2025-2026 Tracker'!$A$2:$A$5000,">="&G3,'2025-2026 Tracker'!$A$2:$A$5000,"<="&EOMONTH(G3,0),'2025-2026 Tracker'!$B$2:$B$5000,"Income",'2025-2026 Tracker'!$C$2:$C$5000,"Grants") -> 0 | H7: =SUMIFS('2025-2026 Tracker'!$K$2:$K$5000,'2025-2026 Tracker'!$A$2:$A$5000,">="&H3,'2025-2026 Tracker'!$A$2:$A$5000,"<="&EOMONTH(H3,0),'2025-2026 Tracker'!$B$2:$B$5000,"Income",'2025-2026 Tracker'!$C$2:$C$5000,"Grants") -> 0 | I7: =SUMIFS('2025-2026 Tracker'!$K$2:$K$5000,'2025-2026 Tracker'!$A$2:$A$5000,">="&I3,'2025-2026 Tracker'!$A$2:$A$5000,"<="&EOMONTH(I3,0),'2025-2026 Tracker'!$B$2:$B$5000,"Income",'2025-2026 Tracker'!$C$2:$C$5000,"Grants") -> 0 | J7: =SUMIFS('2025-2026 Tracker'!$K$2:$K$5000,'2025-2026 Tracker'!$A$2:$A$5000,">="&J3,'2025-2026 Tracker'!$A$2:$A$5000,"<="&EOMONTH(J3,0),'2025-2026 Tracker'!$B$2:$B$5000,"Income",'2025-2026 Tracker'!$C$2:$C$5000,"Grants") -> 0 | ... Z7: =SUMIFS('2025-2026 Tracker'!$K$2:$K$5000,'2025-2026 Tracker'!$A$2:$A$5000,">="&Z3,'2025-2026 Tracker'!$A$2:$A$5000,"<="&EOMONTH(Z3,0),'2025-2026 Tracker'!$B$2:$B$5000,"Income",'2025-2026 Tracker'!$C$2:$C$5000,"Grants") -> 0 | AA7: =SUM(C7:Z7) -> 0
A8: Consulting/Services | C8: =SUMIFS('2025-2026 Tracker'!$K$2:$K$5000,'2025-2026 Tracker'!$A$2:$A$5000,">="&C3,'2025-2026 Tracker'!$A$2:$A$5000,"<="&EOMONTH(C3,0),'2025-2026 Tracker'!$B$2:$B$5000,"Income",'2025-2026 Tracker'!$C$2:$C$5000,"Consulting/Services") -> 0 | D8: =SUMIFS('2025-2026 Tracker'!$K$2:$K$5000,'2025-2026 Tracker'!$A$2:$A$5000,">="&D3,'2025-2026 Tracker'!$A$2:$A$5000,"<="&EOMONTH(D3,0),'2025-2026 Tracker'!$B$2:$B$5000,"Income",'2025-2026 Tracker'!$C$2:$C$5000,"Consulting/Services") -> 0 | E8: =SUMIFS('2025-2026 Tracker'!$K$2:$K$5000,'2025-2026 Tracker'!$A$2:$A$5000,">="&E3,'2025-2026 Tracker'!$A$2:$A$5000,"<="&EOMONTH(E3,0),'2025-2026 Tracker'!$B$2:$B$5000,"Income",'2025-2026 Tracker'!$C$2:$C$5000,"Consulting/Services") -> 0 | F8: =SUMIFS('2025-2026 Tracker'!$K$2:$K$5000,'2025-2026 Tracker'!$A$2:$A$5000,">="&F3,'2025-2026 Tracker'!$A$2:$A$5000,"<="&EOMONTH(F3,0),'2025-2026 Tracker'!$B$2:$B$5000,"Income",'2025-2026 Tracker'!$C$2:$C$5000,"Consulting/Services") -> 0 | G8: =SUMIFS('2025-2026 Tracker'!$K$2:$K$5000,'2025-2026 Tracker'!$A$2:$A$5000,">="&G3,'2025-2026 Tracker'!$A$2:$A$5000,"<="&EOMONTH(G3,0),'2025-2026 Tracker'!$B$2:$B$5000,"Income",'2025-2026 Tracker'!$C$2:$C$5000,"Consulting/Services") -> 0 | H8: =SUMIFS('2025-2026 Tracker'!$K$2:$K$5000,'2025-2026 Tracker'!$A$2:$A$5000,">="&H3,'2025-2026 Tracker'!$A$2:$A$5000,"<="&EOMONTH(H3,0),'2025-2026 Tracker'!$B$2:$B$5000,"Income",'2025-2026 Tracker'!$C$2:$C$5000,"Consulting/Services") -> 0 | I8: =SUMIFS('2025-2026 Tracker'!$K$2:$K$5000,'2025-2026 Tracker'!$A$2:$A$5000,">="&I3,'2025-2026 Tracker'!$A$2:$A$5000,"<="&EOMONTH(I3,0),'2025-2026 Tracker'!$B$2:$B$5000,"Income",'2025-2026 Tracker'!$C$2:$C$5000,"Consulting/Services") -> 0 | J8: =SUMIFS('2025-2026 Tracker'!$K$2:$K$5000,'2025-2026 Tracker'!$A$2:$A$5000,">="&J3,'2025-2026 Tracker'!$A$2:$A$5000,"<="&EOMONTH(J3,0),'2025-2026 Tracker'!$B$2:$B$5000,"Income",'2025-2026 Tracker'!$C$2:$C$5000,"Consulting/Services") -> 0 | ... Z8: =SUMIFS('2025-2026 Tracker'!$K$2:$K$5000,'2025-2026 Tracker'!$A$2:$A$5000,">="&Z3,'2025-2026 Tracker'!$A$2:$A$5000,"<="&EOMONTH(Z3,0),'2025-2026 Tracker'!$B$2:$B$5000,"Income",'2025-2026 Tracker'!$C$2:$C$5000,"Consulting/Services") -> 0 | AA8: =SUM(C8:Z8) -> 0
A9: Other income | C9: =SUMIFS('2025-2026 Tracker'!$K$2:$K$5000,'2025-2026 Tracker'!$A$2:$A$5000,">="&C3,'2025-2026 Tracker'!$A$2:$A$5000,"<="&EOMONTH(C3,0),'2025-2026 Tracker'!$B$2:$B$5000,"Income",'2025-2026 Tracker'!$C$2:$C$5000,"Other income") -> 0 | D9: =SUMIFS('2025-2026 Tracker'!$K$2:$K$5000,'2025-2026 Tracker'!$A$2:$A$5000,">="&D3,'2025-2026 Tracker'!$A$2:$A$5000,"<="&EOMONTH(D3,0),'2025-2026 Tracker'!$B$2:$B$5000,"Income",'2025-2026 Tracker'!$C$2:$C$5000,"Other income") -> 0 | E9: =SUMIFS('2025-2026 Tracker'!$K$2:$K$5000,'2025-2026 Tracker'!$A$2:$A$5000,">="&E3,'2025-2026 Tracker'!$A$2:$A$5000,"<="&EOMONTH(E3,0),'2025-2026 Tracker'!$B$2:$B$5000,"Income",'2025-2026 Tracker'!$C$2:$C$5000,"Other income") -> 0 | F9: =SUMIFS('2025-2026 Tracker'!$K$2:$K$5000,'2025-2026 Tracker'!$A$2:$A$5000,">="&F3,'2025-2026 Tracker'!$A$2:$A$5000,"<="&EOMONTH(F3,0),'2025-2026 Tracker'!$B$2:$B$5000,"Income",'2025-2026 Tracker'!$C$2:$C$5000,"Other income") -> 0 | G9: =SUMIFS('2025-2026 Tracker'!$K$2:$K$5000,'2025-2026 Tracker'!$A$2:$A$5000,">="&G3,'2025-2026 Tracker'!$A$2:$A$5000,"<="&EOMONTH(G3,0),'2025-2026 Tracker'!$B$2:$B$5000,"Income",'2025-2026 Tracker'!$C$2:$C$5000,"Other income") -> 0 | H9: =SUMIFS('2025-2026 Tracker'!$K$2:$K$5000,'2025-2026 Tracker'!$A$2:$A$5000,">="&H3,'2025-2026 Tracker'!$A$2:$A$5000,"<="&EOMONTH(H3,0),'2025-2026 Tracker'!$B$2:$B$5000,"Income",'2025-2026 Tracker'!$C$2:$C$5000,"Other income") -> 0 | I9: =SUMIFS('2025-2026 Tracker'!$K$2:$K$5000,'2025-2026 Tracker'!$A$2:$A$5000,">="&I3,'2025-2026 Tracker'!$A$2:$A$5000,"<="&EOMONTH(I3,0),'2025-2026 Tracker'!$B$2:$B$5000,"Income",'2025-2026 Tracker'!$C$2:$C$5000,"Other income") -> 0 | J9: =SUMIFS('2025-2026 Tracker'!$K$2:$K$5000,'2025-2026 Tracker'!$A$2:$A$5000,">="&J3,'2025-2026 Tracker'!$A$2:$A$5000,"<="&EOMONTH(J3,0),'2025-2026 Tracker'!$B$2:$B$5000,"Income",'2025-2026 Tracker'!$C$2:$C$5000,"Other income") -> 0 | ... Z9: =SUMIFS('2025-2026 Tracker'!$K$2:$K$5000,'2025-2026 Tracker'!$A$2:$A$5000,">="&Z3,'2025-2026 Tracker'!$A$2:$A$5000,"<="&EOMONTH(Z3,0),'2025-2026 Tracker'!$B$2:$B$5000,"Income",'2025-2026 Tracker'!$C$2:$C$5000,"Other income") -> 0 | AA9: =SUM(C9:Z9) -> 0
A11: Expenses | C11: =C12+C19 -> 13.92 | D11: =D12+D19 -> 59.6 | E11: =E12+E19 -> 13.92 | F11: =F12+F19 -> 13.92 | G11: =G12+G19 -> 13.92 | H11: =H12+H19 -> 13.92 | I11: =I12+I19 -> 13.92 | J11: =J12+J19 -> 13.92 | ... N11: =N12+N19 -> 13.92 | AA11: =SUM(C11:Z11) -> 212.72
A12: Fixed costs | C12: =SUM(C13:C17) -> 13.92 | D12: =SUM(D13:D17) -> 59.6 | E12: =SUM(E13:E17) -> 13.92 | F12: =SUM(F13:F17) -> 13.92 | G12: =SUM(G13:G17) -> 13.92 | H12: =SUM(H13:H17) -> 13.92 | I12: =SUM(I13:I17) -> 13.92 | J12: =SUM(J13:J17) -> 13.92 | ... N12: =SUM(N13:N17) -> 13.92 | AA12: =SUM(C12:Z12) -> 212.72
A13: Obsidian Publish | C13: =SUMIFS('2025-2026 Tracker'!$K$2:$K$5000,'2025-2026 Tracker'!$A$2:$A$5000,">="&C3,'2025-2026 Tracker'!$A$2:$A$5000,"<="&EOMONTH(C3,0),'2025-2026 Tracker'!$B$2:$B$5000,"Expense",'2025-2026 Tracker'!$C$2:$C$5000,"Fixed costs",'2025-2026 Tracker'!$D$2:$D$5000,"Obsidian Publish") -> 0 | D13: =SUMIFS('2025-2026 Tracker'!$K$2:$K$5000,'2025-2026 Tracker'!$A$2:$A$5000,">="&D3,'2025-2026 Tracker'!$A$2:$A$5000,"<="&EOMONTH(D3,0),'2025-2026 Tracker'!$B$2:$B$5000,"Expense",'2025-2026 Tracker'!$C$2:$C$5000,"Fixed costs",'2025-2026 Tracker'!$D$2:$D$5000,"Obsidian Publish") -> 0 | E13: =SUMIFS('2025-2026 Tracker'!$K$2:$K$5000,'2025-2026 Tracker'!$A$2:$A$5000,">="&E3,'2025-2026 Tracker'!$A$2:$A$5000,"<="&EOMONTH(E3,0),'2025-2026 Tracker'!$B$2:$B$5000,"Expense",'2025-2026 Tracker'!$C$2:$C$5000,"Fixed costs",'2025-2026 Tracker'!$D$2:$D$5000,"Obsidian Publish") -> 0 | F13: =SUMIFS('2025-2026 Tracker'!$K$2:$K$5000,'2025-2026 Tracker'!$A$2:$A$5000,">="&F3,'2025-2026 Tracker'!$A$2:$A$5000,"<="&EOMONTH(F3,0),'2025-2026 Tracker'!$B$2:$B$5000,"Expense",'2025-2026 Tracker'!$C$2:$C$5000,"Fixed costs",'2025-2026 Tracker'!$D$2:$D$5000,"Obsidian Publish") -> 0 | G13: =SUMIFS('2025-2026 Tracker'!$K$2:$K$5000,'2025-2026 Tracker'!$A$2:$A$5000,">="&G3,'2025-2026 Tracker'!$A$2:$A$5000,"<="&EOMONTH(G3,0),'2025-2026 Tracker'!$B$2:$B$5000,"Expense",'2025-2026 Tracker'!$C$2:$C$5000,"Fixed costs",'2025-2026 Tracker'!$D$2:$D$5000,"Obsidian Publish") -> 0 | H13: =SUMIFS('2025-2026 Tracker'!$K$2:$K$5000,'2025-2026 Tracker'!$A$2:$A$5000,">="&H3,'2025-2026 Tracker'!$A$2:$A$5000,"<="&EOMONTH(H3,0),'2025-2026 Tracker'!$B$2:$B$5000,"Expense",'2025-2026 Tracker'!$C$2:$C$5000,"Fixed costs",'2025-2026 Tracker'!$D$2:$D$5000,"Obsidian Publish") -> 0 | I13: =SUMIFS('2025-2026 Tracker'!$K$2:$K$5000,'2025-2026 Tracker'!$A$2:$A$5000,">="&I3,'2025-2026 Tracker'!$A$2:$A$5000,"<="&EOMONTH(I3,0),'2025-2026 Tracker'!$B$2:$B$5000,"Expense",'2025-2026 Tracker'!$C$2:$C$5000,"Fixed costs",'2025-2026 Tracker'!$D$2:$D$5000,"Obsidian Publish") -> 0 | J13: =SUMIFS('2025-2026 Tracker'!$K$2:$K$5000,'2025-2026 Tracker'!$A$2:$A$5000,">="&J3,'2025-2026 Tracker'!$A$2:$A$5000,"<="&EOMONTH(J3,0),'2025-2026 Tracker'!$B$2:$B$5000,"Expense",'2025-2026 Tracker'!$C$2:$C$5000,"Fixed costs",'2025-2026 Tracker'!$D$2:$D$5000,"Obsidian Publish") -> 0 | ... Z13: =SUMIFS('2025-2026 Tracker'!$K$2:$K$5000,'2025-2026 Tracker'!$A$2:$A$5000,">="&Z3,'2025-2026 Tracker'!$A$2:$A$5000,"<="&EOMONTH(Z3,0),'2025-2026 Tracker'!$B$2:$B$5000,"Expense",'2025-2026 Tracker'!$C$2:$C$5000,"Fixed costs",'2025-2026 Tracker'!$D$2:$D$5000,"Obsidian Publish") -> 0 | AA13: =SUM(C13:Z13) -> 0
A14: refibcn.cat domain | C14: =SUMIFS('2025-2026 Tracker'!$K$2:$K$5000,'2025-2026 Tracker'!$A$2:$A$5000,">="&C3,'2025-2026 Tracker'!$A$2:$A$5000,"<="&EOMONTH(C3,0),'2025-2026 Tracker'!$B$2:$B$5000,"Expense",'2025-2026 Tracker'!$C$2:$C$5000,"Fixed costs",'2025-2026 Tracker'!$D$2:$D$5000,"refibcn.cat domain") -> 0 | D14: =SUMIFS('2025-2026 Tracker'!$K$2:$K$5000,'2025-2026 Tracker'!$A$2:$A$5000,">="&D3,'2025-2026 Tracker'!$A$2:$A$5000,"<="&EOMONTH(D3,0),'2025-2026 Tracker'!$B$2:$B$5000,"Expense",'2025-2026 Tracker'!$C$2:$C$5000,"Fixed costs",'2025-2026 Tracker'!$D$2:$D$5000,"refibcn.cat domain") -> 45.68 | E14: =SUMIFS('2025-2026 Tracker'!$K$2:$K$5000,'2025-2026 Tracker'!$A$2:$A$5000,">="&E3,'2025-2026 Tracker'!$A$2:$A$5000,"<="&EOMONTH(E3,0),'2025-2026 Tracker'!$B$2:$B$5000,"Expense",'2025-2026 Tracker'!$C$2:$C$5000,"Fixed costs",'2025-2026 Tracker'!$D$2:$D$5000,"refibcn.cat domain") -> 0 | F14: =SUMIFS('2025-2026 Tracker'!$K$2:$K$5000,'2025-2026 Tracker'!$A$2:$A$5000,">="&F3,'2025-2026 Tracker'!$A$2:$A$5000,"<="&EOMONTH(F3,0),'2025-2026 Tracker'!$B$2:$B$5000,"Expense",'2025-2026 Tracker'!$C$2:$C$5000,"Fixed costs",'2025-2026 Tracker'!$D$2:$D$5000,"refibcn.cat domain") -> 0 | G14: =SUMIFS('2025-2026 Tracker'!$K$2:$K$5000,'2025-2026 Tracker'!$A$2:$A$5000,">="&G3,'2025-2026 Tracker'!$A$2:$A$5000,"<="&EOMONTH(G3,0),'2025-2026 Tracker'!$B$2:$B$5000,"Expense",'2025-2026 Tracker'!$C$2:$C$5000,"Fixed costs",'2025-2026 Tracker'!$D$2:$D$5000,"refibcn.cat domain") -> 0 | H14: =SUMIFS('2025-2026 Tracker'!$K$2:$K$5000,'2025-2026 Tracker'!$A$2:$A$5000,">="&H3,'2025-2026 Tracker'!$A$2:$A$5000,"<="&EOMONTH(H3,0),'2025-2026 Tracker'!$B$2:$B$5000,"Expense",'2025-2026 Tracker'!$C$2:$C$5000,"Fixed costs",'2025-2026 Tracker'!$D$2:$D$5000,"refibcn.cat domain") -> 0 | I14: =SUMIFS('2025-2026 Tracker'!$K$2:$K$5000,'2025-2026 Tracker'!$A$2:$A$5000,">="&I3,'2025-2026 Tracker'!$A$2:$A$5000,"<="&EOMONTH(I3,0),'2025-2026 Tracker'!$B$2:$B$5000,"Expense",'2025-2026 Tracker'!$C$2:$C$5000,"Fixed costs",'2025-2026 Tracker'!$D$2:$D$5000,"refibcn.cat domain") -> 0 | J14: =SUMIFS('2025-2026 Tracker'!$K$2:$K$5000,'2025-2026 Tracker'!$A$2:$A$5000,">="&J3,'2025-2026 Tracker'!$A$2:$A$5000,"<="&EOMONTH(J3,0),'2025-2026 Tracker'!$B$2:$B$5000,"Expense",'2025-2026 Tracker'!$C$2:$C$5000,"Fixed costs",'2025-2026 Tracker'!$D$2:$D$5000,"refibcn.cat domain") -> 0 | ... Z14: =SUMIFS('2025-2026 Tracker'!$K$2:$K$5000,'2025-2026 Tracker'!$A$2:$A$5000,">="&Z3,'2025-2026 Tracker'!$A$2:$A$5000,"<="&EOMONTH(Z3,0),'2025-2026 Tracker'!$B$2:$B$5000,"Expense",'2025-2026 Tracker'!$C$2:$C$5000,"Fixed costs",'2025-2026 Tracker'!$D$2:$D$5000,"refibcn.cat domain") -> 0 | AA14: =SUM(C14:Z14) -> 45.68
A15: Notion | C15: =SUMIFS('2025-2026 Tracker'!$K$2:$K$5000,'2025-2026 Tracker'!$A$2:$A$5000,">="&C3,'2025-2026 Tracker'!$A$2:$A$5000,"<="&EOMONTH(C3,0),'2025-2026 Tracker'!$B$2:$B$5000,"Expense",'2025-2026 Tracker'!$C$2:$C$5000,"Fixed costs",'2025-2026 Tracker'!$D$2:$D$5000,"Notion") -> 13.92 | D15: =SUMIFS('2025-2026 Tracker'!$K$2:$K$5000,'2025-2026 Tracker'!$A$2:$A$5000,">="&D3,'2025-2026 Tracker'!$A$2:$A$5000,"<="&EOMONTH(D3,0),'2025-2026 Tracker'!$B$2:$B$5000,"Expense",'2025-2026 Tracker'!$C$2:$C$5000,"Fixed costs",'2025-2026 Tracker'!$D$2:$D$5000,"Notion") -> 13.92 | E15: =SUMIFS('2025-2026 Tracker'!$K$2:$K$5000,'2025-2026 Tracker'!$A$2:$A$5000,">="&E3,'2025-2026 Tracker'!$A$2:$A$5000,"<="&EOMONTH(E3,0),'2025-2026 Tracker'!$B$2:$B$5000,"Expense",'2025-2026 Tracker'!$C$2:$C$5000,"Fixed costs",'2025-2026 Tracker'!$D$2:$D$5000,"Notion") -> 13.92 | F15: =SUMIFS('2025-2026 Tracker'!$K$2:$K$5000,'2025-2026 Tracker'!$A$2:$A$5000,">="&F3,'2025-2026 Tracker'!$A$2:$A$5000,"<="&EOMONTH(F3,0),'2025-2026 Tracker'!$B$2:$B$5000,"Expense",'2025-2026 Tracker'!$C$2:$C$5000,"Fixed costs",'2025-2026 Tracker'!$D$2:$D$5000,"Notion") -> 13.92 | G15: =SUMIFS('2025-2026 Tracker'!$K$2:$K$5000,'2025-2026 Tracker'!$A$2:$A$5000,">="&G3,'2025-2026 Tracker'!$A$2:$A$5000,"<="&EOMONTH(G3,0),'2025-2026 Tracker'!$B$2:$B$5000,"Expense",'2025-2026 Tracker'!$C$2:$C$5000,"Fixed costs",'2025-2026 Tracker'!$D$2:$D$5000,"Notion") -> 13.92 | H15: =SUMIFS('2025-2026 Tracker'!$K$2:$K$5000,'2025-2026 Tracker'!$A$2:$A$5000,">="&H3,'2025-2026 Tracker'!$A$2:$A$5000,"<="&EOMONTH(H3,0),'2025-2026 Tracker'!$B$2:$B$5000,"Expense",'2025-2026 Tracker'!$C$2:$C$5000,"Fixed costs",'2025-2026 Tracker'!$D$2:$D$5000,"Notion") -> 13.92 | I15: =SUMIFS('2025-2026 Tracker'!$K$2:$K$5000,'2025-2026 Tracker'!$A$2:$A$5000,">="&I3,'2025-2026 Tracker'!$A$2:$A$5000,"<="&EOMONTH(I3,0),'2025-2026 Tracker'!$B$2:$B$5000,"Expense",'2025-2026 Tracker'!$C$2:$C$5000,"Fixed costs",'2025-2026 Tracker'!$D$2:$D$5000,"Notion") -> 13.92 | J15: =SUMIFS('2025-2026 Tracker'!$K$2:$K$5000,'2025-2026 Tracker'!$A$2:$A$5000,">="&J3,'2025-2026 Tracker'!$A$2:$A$5000,"<="&EOMONTH(J3,0),'2025-2026 Tracker'!$B$2:$B$5000,"Expense",'2025-2026 Tracker'!$C$2:$C$5000,"Fixed costs",'2025-2026 Tracker'!$D$2:$D$5000,"Notion") -> 13.92 | ... Z15: =SUMIFS('2025-2026 Tracker'!$K$2:$K$5000,'2025-2026 Tracker'!$A$2:$A$5000,">="&Z3,'2025-2026 Tracker'!$A$2:$A$5000,"<="&EOMONTH(Z3,0),'2025-2026 Tracker'!$B$2:$B$5000,"Expense",'2025-2026 Tracker'!$C$2:$C$5000,"Fixed costs",'2025-2026 Tracker'!$D$2:$D$5000,"Notion") -> 13.92 | AA15: =SUM(C15:Z15) -> 334.08
A16: Cursor Team | C16: =SUMIFS('2025-2026 Tracker'!$K$2:$K$5000,'2025-2026 Tracker'!$A$2:$A$5000,">="&C3,'2025-2026 Tracker'!$A$2:$A$5000,"<="&EOMONTH(C3,0),'2025-2026 Tracker'!$B$2:$B$5000,"Expense",'2025-2026 Tracker'!$C$2:$C$5000,"Fixed costs",'2025-2026 Tracker'!$D$2:$D$5000,"Cursor Team") -> 0 | D16: =SUMIFS('2025-2026 Tracker'!$K$2:$K$5000,'2025-2026 Tracker'!$A$2:$A$5000,">="&D3,'2025-2026 Tracker'!$A$2:$A$5000,"<="&EOMONTH(D3,0),'2025-2026 Tracker'!$B$2:$B$5000,"Expense",'2025-2026 Tracker'!$C$2:$C$5000,"Fixed costs",'2025-2026 Tracker'!$D$2:$D$5000,"Cursor Team") -> 0 | E16: =SUMIFS('2025-2026 Tracker'!$K$2:$K$5000,'2025-2026 Tracker'!$A$2:$A$5000,">="&E3,'2025-2026 Tracker'!$A$2:$A$5000,"<="&EOMONTH(E3,0),'2025-2026 Tracker'!$B$2:$B$5000,"Expense",'2025-2026 Tracker'!$C$2:$C$5000,"Fixed costs",'2025-2026 Tracker'!$D$2:$D$5000,"Cursor Team") -> 0 | F16: =SUMIFS('2025-2026 Tracker'!$K$2:$K$5000,'2025-2026 Tracker'!$A$2:$A$5000,">="&F3,'2025-2026 Tracker'!$A$2:$A$5000,"<="&EOMONTH(F3,0),'2025-2026 Tracker'!$B$2:$B$5000,"Expense",'2025-2026 Tracker'!$C$2:$C$5000,"Fixed costs",'2025-2026 Tracker'!$D$2:$D$5000,"Cursor Team") -> 0 | G16: =SUMIFS('2025-2026 Tracker'!$K$2:$K$5000,'2025-2026 Tracker'!$A$2:$A$5000,">="&G3,'2025-2026 Tracker'!$A$2:$A$5000,"<="&EOMONTH(G3,0),'2025-2026 Tracker'!$B$2:$B$5000,"Expense",'2025-2026 Tracker'!$C$2:$C$5000,"Fixed costs",'2025-2026 Tracker'!$D$2:$D$5000,"Cursor Team") -> 0 | H16: =SUMIFS('2025-2026 Tracker'!$K$2:$K$5000,'2025-2026 Tracker'!$A$2:$A$5000,">="&H3,'2025-2026 Tracker'!$A$2:$A$5000,"<="&EOMONTH(H3,0),'2025-2026 Tracker'!$B$2:$B$5000,"Expense",'2025-2026 Tracker'!$C$2:$C$5000,"Fixed costs",'2025-2026 Tracker'!$D$2:$D$5000,"Cursor Team") -> 0 | I16: =SUMIFS('2025-2026 Tracker'!$K$2:$K$5000,'2025-2026 Tracker'!$A$2:$A$5000,">="&I3,'2025-2026 Tracker'!$A$2:$A$5000,"<="&EOMONTH(I3,0),'2025-2026 Tracker'!$B$2:$B$5000,"Expense",'2025-2026 Tracker'!$C$2:$C$5000,"Fixed costs",'2025-2026 Tracker'!$D$2:$D$5000,"Cursor Team") -> 0 | J16: =SUMIFS('2025-2026 Tracker'!$K$2:$K$5000,'2025-2026 Tracker'!$A$2:$A$5000,">="&J3,'2025-2026 Tracker'!$A$2:$A$5000,"<="&EOMONTH(J3,0),'2025-2026 Tracker'!$B$2:$B$5000,"Expense",'2025-2026 Tracker'!$C$2:$C$5000,"Fixed costs",'2025-2026 Tracker'!$D$2:$D$5000,"Cursor Team") -> 0 | ... Z16: =SUMIFS('2025-2026 Tracker'!$K$2:$K$5000,'2025-2026 Tracker'!$A$2:$A$5000,">="&Z3,'2025-2026 Tracker'!$A$2:$A$5000,"<="&EOMONTH(Z3,0),'2025-2026 Tracker'!$B$2:$B$5000,"Expense",'2025-2026 Tracker'!$C$2:$C$5000,"Fixed costs",'2025-2026 Tracker'!$D$2:$D$5000,"Cursor Team") -> 0 | AA16: =SUM(C16:Z16) -> 0
A17: Other fixed | AA17: =SUM(C17:Z17) -> 0
A19: Variable costs | C19: =SUM(C20:C27) -> 0 | D19: =SUM(D20:D27) -> 0 | E19: =SUM(E20:E27) -> 0 | F19: =SUM(F20:F27) -> 0 | G19: =SUM(G20:G27) -> 0 | H19: =SUM(H20:H27) -> 0 | I19: =SUM(I20:I27) -> 0 | J19: =SUM(J20:J27) -> 0 | ... N19: =SUM(N20:N27) -> 0 | AA19: =SUM(C19:Z19) -> 0
A20: Project-specific expenses | C20: =SUMIFS('2025-2026 Tracker'!$K$2:$K$5000,'2025-2026 Tracker'!$A$2:$A$5000,">="&C3,'2025-2026 Tracker'!$A$2:$A$5000,"<="&EOMONTH(C3,0),'2025-2026 Tracker'!$B$2:$B$5000,"Expense",'2025-2026 Tracker'!$C$2:$C$5000,"Project-specific expenses") -> 0 | D20: =SUMIFS('2025-2026 Tracker'!$K$2:$K$5000,'2025-2026 Tracker'!$A$2:$A$5000,">="&D3,'2025-2026 Tracker'!$A$2:$A$5000,"<="&EOMONTH(D3,0),'2025-2026 Tracker'!$B$2:$B$5000,"Expense",'2025-2026 Tracker'!$C$2:$C$5000,"Project-specific expenses") -> 0 | E20: =SUMIFS('2025-2026 Tracker'!$K$2:$K$5000,'2025-2026 Tracker'!$A$2:$A$5000,">="&E3,'2025-2026 Tracker'!$A$2:$A$5000,"<="&EOMONTH(E3,0),'2025-2026 Tracker'!$B$2:$B$5000,"Expense",'2025-2026 Tracker'!$C$2:$C$5000,"Project-specific expenses") -> 0 | F20: =SUMIFS('2025-2026 Tracker'!$K$2:$K$5000,'2025-2026 Tracker'!$A$2:$A$5000,">="&F3,'2025-2026 Tracker'!$A$2:$A$5000,"<="&EOMONTH(F3,0),'2025-2026 Tracker'!$B$2:$B$5000,"Expense",'2025-2026 Tracker'!$C$2:$C$5000,"Project-specific expenses") -> 0 | G20: =SUMIFS('2025-2026 Tracker'!$K$2:$K$5000,'2025-2026 Tracker'!$A$2:$A$5000,">="&G3,'2025-2026 Tracker'!$A$2:$A$5000,"<="&EOMONTH(G3,0),'2025-2026 Tracker'!$B$2:$B$5000,"Expense",'2025-2026 Tracker'!$C$2:$C$5000,"Project-specific expenses") -> 0 | H20: =SUMIFS('2025-2026 Tracker'!$K$2:$K$5000,'2025-2026 Tracker'!$A$2:$A$5000,">="&H3,'2025-2026 Tracker'!$A$2:$A$5000,"<="&EOMONTH(H3,0),'2025-2026 Tracker'!$B$2:$B$5000,"Expense",'2025-2026 Tracker'!$C$2:$C$5000,"Project-specific expenses") -> 0 | I20: =SUMIFS('2025-2026 Tracker'!$K$2:$K$5000,'2025-2026 Tracker'!$A$2:$A$5000,">="&I3,'2025-2026 Tracker'!$A$2:$A$5000,"<="&EOMONTH(I3,0),'2025-2026 Tracker'!$B$2:$B$5000,"Expense",'2025-2026 Tracker'!$C$2:$C$5000,"Project-specific expenses") -> 0 | J20: =SUMIFS('2025-2026 Tracker'!$K$2:$K$5000,'2025-2026 Tracker'!$A$2:$A$5000,">="&J3,'2025-2026 Tracker'!$A$2:$A$5000,"<="&EOMONTH(J3,0),'2025-2026 Tracker'!$B$2:$B$5000,"Expense",'2025-2026 Tracker'!$C$2:$C$5000,"Project-specific expenses") -> 0 | ... Z20: =SUMIFS('2025-2026 Tracker'!$K$2:$K$5000,'2025-2026 Tracker'!$A$2:$A$5000,">="&Z3,'2025-2026 Tracker'!$A$2:$A$5000,"<="&EOMONTH(Z3,0),'2025-2026 Tracker'!$B$2:$B$5000,"Expense",'2025-2026 Tracker'!$C$2:$C$5000,"Project-specific expenses") -> 0 | AA20: =SUM(C20:Z20) -> 0
A21: Events & workshops | C21: =SUMIFS('2025-2026 Tracker'!$K$2:$K$5000,'2025-2026 Tracker'!$A$2:$A$5000,">="&C3,'2025-2026 Tracker'!$A$2:$A$5000,"<="&EOMONTH(C3,0),'2025-2026 Tracker'!$B$2:$B$5000,"Expense",'2025-2026 Tracker'!$C$2:$C$5000,"Events & workshops") -> 0 | D21: =SUMIFS('2025-2026 Tracker'!$K$2:$K$5000,'2025-2026 Tracker'!$A$2:$A$5000,">="&D3,'2025-2026 Tracker'!$A$2:$A$5000,"<="&EOMONTH(D3,0),'2025-2026 Tracker'!$B$2:$B$5000,"Expense",'2025-2026 Tracker'!$C$2:$C$5000,"Events & workshops") -> 0 | E21: =SUMIFS('2025-2026 Tracker'!$K$2:$K$5000,'2025-2026 Tracker'!$A$2:$A$5000,">="&E3,'2025-2026 Tracker'!$A$2:$A$5000,"<="&EOMONTH(E3,0),'2025-2026 Tracker'!$B$2:$B$5000,"Expense",'2025-2026 Tracker'!$C$2:$C$5000,"Events & workshops") -> 0 | F21: =SUMIFS('2025-2026 Tracker'!$K$2:$K$5000,'2025-2026 Tracker'!$A$2:$A$5000,">="&F3,'2025-2026 Tracker'!$A$2:$A$5000,"<="&EOMONTH(F3,0),'2025-2026 Tracker'!$B$2:$B$5000,"Expense",'2025-2026 Tracker'!$C$2:$C$5000,"Events & workshops") -> 0 | G21: =SUMIFS('2025-2026 Tracker'!$K$2:$K$5000,'2025-2026 Tracker'!$A$2:$A$5000,">="&G3,'2025-2026 Tracker'!$A$2:$A$5000,"<="&EOMONTH(G3,0),'2025-2026 Tracker'!$B$2:$B$5000,"Expense",'2025-2026 Tracker'!$C$2:$C$5000,"Events & workshops") -> 0 | H21: =SUMIFS('2025-2026 Tracker'!$K$2:$K$5000,'2025-2026 Tracker'!$A$2:$A$5000,">="&H3,'2025-2026 Tracker'!$A$2:$A$5000,"<="&EOMONTH(H3,0),'2025-2026 Tracker'!$B$2:$B$5000,"Expense",'2025-2026 Tracker'!$C$2:$C$5000,"Events & workshops") -> 0 | I21: =SUMIFS('2025-2026 Tracker'!$K$2:$K$5000,'2025-2026 Tracker'!$A$2:$A$5000,">="&I3,'2025-2026 Tracker'!$A$2:$A$5000,"<="&EOMONTH(I3,0),'2025-2026 Tracker'!$B$2:$B$5000,"Expense",'2025-2026 Tracker'!$C$2:$C$5000,"Events & workshops") -> 0 | J21: =SUMIFS('2025-2026 Tracker'!$K$2:$K$5000,'2025-2026 Tracker'!$A$2:$A$5000,">="&J3,'2025-2026 Tracker'!$A$2:$A$5000,"<="&EOMONTH(J3,0),'2025-2026 Tracker'!$B$2:$B$5000,"Expense",'2025-2026 Tracker'!$C$2:$C$5000,"Events & workshops") -> 0 | ... Z21: =SUMIFS('2025-2026 Tracker'!$K$2:$K$5000,'2025-2026 Tracker'!$A$2:$A$5000,">="&Z3,'2025-2026 Tracker'!$A$2:$A$5000,"<="&EOMONTH(Z3,0),'2025-2026 Tracker'!$B$2:$B$5000,"Expense",'2025-2026 Tracker'!$C$2:$C$5000,"Events & workshops") -> 0 | AA21: =SUM(C21:Z21) -> 0
A22: Marketing/Comms | C22: =SUMIFS('2025-2026 Tracker'!$K$2:$K$5000,'2025-2026 Tracker'!$A$2:$A$5000,">="&C3,'2025-2026 Tracker'!$A$2:$A$5000,"<="&EOMONTH(C3,0),'2025-2026 Tracker'!$B$2:$B$5000,"Expense",'2025-2026 Tracker'!$C$2:$C$5000,"Marketing/Comms") -> 0 | D22: =SUMIFS('2025-2026 Tracker'!$K$2:$K$5000,'2025-2026 Tracker'!$A$2:$A$5000,">="&D3,'2025-2026 Tracker'!$A$2:$A$5000,"<="&EOMONTH(D3,0),'2025-2026 Tracker'!$B$2:$B$5000,"Expense",'2025-2026 Tracker'!$C$2:$C$5000,"Marketing/Comms") -> 0 | E22: =SUMIFS('2025-2026 Tracker'!$K$2:$K$5000,'2025-2026 Tracker'!$A$2:$A$5000,">="&E3,'2025-2026 Tracker'!$A$2:$A$5000,"<="&EOMONTH(E3,0),'2025-2026 Tracker'!$B$2:$B$5000,"Expense",'2025-2026 Tracker'!$C$2:$C$5000,"Marketing/Comms") -> 0 | F22: =SUMIFS('2025-2026 Tracker'!$K$2:$K$5000,'2025-2026 Tracker'!$A$2:$A$5000,">="&F3,'2025-2026 Tracker'!$A$2:$A$5000,"<="&EOMONTH(F3,0),'2025-2026 Tracker'!$B$2:$B$5000,"Expense",'2025-2026 Tracker'!$C$2:$C$5000,"Marketing/Comms") -> 0 | G22: =SUMIFS('2025-2026 Tracker'!$K$2:$K$5000,'2025-2026 Tracker'!$A$2:$A$5000,">="&G3,'2025-2026 Tracker'!$A$2:$A$5000,"<="&EOMONTH(G3,0),'2025-2026 Tracker'!$B$2:$B$5000,"Expense",'2025-2026 Tracker'!$C$2:$C$5000,"Marketing/Comms") -> 0 | H22: =SUMIFS('2025-2026 Tracker'!$K$2:$K$5000,'2025-2026 Tracker'!$A$2:$A$5000,">="&H3,'2025-2026 Tracker'!$A$2:$A$5000,"<="&EOMONTH(H3,0),'2025-2026 Tracker'!$B$2:$B$5000,"Expense",'2025-2026 Tracker'!$C$2:$C$5000,"Marketing/Comms") -> 0 | I22: =SUMIFS('2025-2026 Tracker'!$K$2:$K$5000,'2025-2026 Tracker'!$A$2:$A$5000,">="&I3,'2025-2026 Tracker'!$A$2:$A$5000,"<="&EOMONTH(I3,0),'2025-2026 Tracker'!$B$2:$B$5000,"Expense",'2025-2026 Tracker'!$C$2:$C$5000,"Marketing/Comms") -> 0 | J22: =SUMIFS('2025-2026 Tracker'!$K$2:$K$5000,'2025-2026 Tracker'!$A$2:$A$5000,">="&J3,'2025-2026 Tracker'!$A$2:$A$5000,"<="&EOMONTH(J3,0),'2025-2026 Tracker'!$B$2:$B$5000,"Expense",'2025-2026 Tracker'!$C$2:$C$5000,"Marketing/Comms") -> 0 | ... Z22: =SUMIFS('2025-2026 Tracker'!$K$2:$K$5000,'2025-2026 Tracker'!$A$2:$A$5000,">="&Z3,'2025-2026 Tracker'!$A$2:$A$5000,"<="&EOMONTH(Z3,0),'2025-2026 Tracker'!$B$2:$B$5000,"Expense",'2025-2026 Tracker'!$C$2:$C$5000,"Marketing/Comms") -> 0 | AA22: =SUM(C22:Z22) -> 0
A23: Professional services | C23: =SUMIFS('2025-2026 Tracker'!$K$2:$K$5000,'2025-2026 Tracker'!$A$2:$A$5000,">="&C3,'2025-2026 Tracker'!$A$2:$A$5000,"<="&EOMONTH(C3,0),'2025-2026 Tracker'!$B$2:$B$5000,"Expense",'2025-2026 Tracker'!$C$2:$C$5000,"Professional services") -> 0 | D23: =SUMIFS('2025-2026 Tracker'!$K$2:$K$5000,'2025-2026 Tracker'!$A$2:$A$5000,">="&D3,'2025-2026 Tracker'!$A$2:$A$5000,"<="&EOMONTH(D3,0),'2025-2026 Tracker'!$B$2:$B$5000,"Expense",'2025-2026 Tracker'!$C$2:$C$5000,"Professional services") -> 0 | E23: =SUMIFS('2025-2026 Tracker'!$K$2:$K$5000,'2025-2026 Tracker'!$A$2:$A$5000,">="&E3,'2025-2026 Tracker'!$A$2:$A$5000,"<="&EOMONTH(E3,0),'2025-2026 Tracker'!$B$2:$B$5000,"Expense",'2025-2026 Tracker'!$C$2:$C$5000,"Professional services") -> 0 | F23: =SUMIFS('2025-2026 Tracker'!$K$2:$K$5000,'2025-2026 Tracker'!$A$2:$A$5000,">="&F3,'2025-2026 Tracker'!$A$2:$A$5000,"<="&EOMONTH(F3,0),'2025-2026 Tracker'!$B$2:$B$5000,"Expense",'2025-2026 Tracker'!$C$2:$C$5000,"Professional services") -> 0 | G23: =SUMIFS('2025-2026 Tracker'!$K$2:$K$5000,'2025-2026 Tracker'!$A$2:$A$5000,">="&G3,'2025-2026 Tracker'!$A$2:$A$5000,"<="&EOMONTH(G3,0),'2025-2026 Tracker'!$B$2:$B$5000,"Expense",'2025-2026 Tracker'!$C$2:$C$5000,"Professional services") -> 0 | H23: =SUMIFS('2025-2026 Tracker'!$K$2:$K$5000,'2025-2026 Tracker'!$A$2:$A$5000,">="&H3,'2025-2026 Tracker'!$A$2:$A$5000,"<="&EOMONTH(H3,0),'2025-2026 Tracker'!$B$2:$B$5000,"Expense",'2025-2026 Tracker'!$C$2:$C$5000,"Professional services") -> 0 | I23: =SUMIFS('2025-2026 Tracker'!$K$2:$K$5000,'2025-2026 Tracker'!$A$2:$A$5000,">="&I3,'2025-2026 Tracker'!$A$2:$A$5000,"<="&EOMONTH(I3,0),'2025-2026 Tracker'!$B$2:$B$5000,"Expense",'2025-2026 Tracker'!$C$2:$C$5000,"Professional services") -> 0 | J23: =SUMIFS('2025-2026 Tracker'!$K$2:$K$5000,'2025-2026 Tracker'!$A$2:$A$5000,">="&J3,'2025-2026 Tracker'!$A$2:$A$5000,"<="&EOMONTH(J3,0),'2025-2026 Tracker'!$B$2:$B$5000,"Expense",'2025-2026 Tracker'!$C$2:$C$5000,"Professional services") -> 0 | ... Z23: =SUMIFS('2025-2026 Tracker'!$K$2:$K$5000,'2025-2026 Tracker'!$A$2:$A$5000,">="&Z3,'2025-2026 Tracker'!$A$2:$A$5000,"<="&EOMONTH(Z3,0),'2025-2026 Tracker'!$B$2:$B$5000,"Expense",'2025-2026 Tracker'!$C$2:$C$5000,"Professional services") -> 0 | AA23: =SUM(C23:Z23) -> 0
A24: Infrastructure/Hosting | C24: =SUMIFS('2025-2026 Tracker'!$K$2:$K$5000,'2025-2026 Tracker'!$A$2:$A$5000,">="&C3,'2025-2026 Tracker'!$A$2:$A$5000,"<="&EOMONTH(C3,0),'2025-2026 Tracker'!$B$2:$B$5000,"Expense",'2025-2026 Tracker'!$C$2:$C$5000,"Infrastructure/Hosting") -> 0 | D24: =SUMIFS('2025-2026 Tracker'!$K$2:$K$5000,'2025-2026 Tracker'!$A$2:$A$5000,">="&D3,'2025-2026 Tracker'!$A$2:$A$5000,"<="&EOMONTH(D3,0),'2025-2026 Tracker'!$B$2:$B$5000,"Expense",'2025-2026 Tracker'!$C$2:$C$5000,"Infrastructure/Hosting") -> 0 | E24: =SUMIFS('2025-2026 Tracker'!$K$2:$K$5000,'2025-2026 Tracker'!$A$2:$A$5000,">="&E3,'2025-2026 Tracker'!$A$2:$A$5000,"<="&EOMONTH(E3,0),'2025-2026 Tracker'!$B$2:$B$5000,"Expense",'2025-2026 Tracker'!$C$2:$C$5000,"Infrastructure/Hosting") -> 0 | F24: =SUMIFS('2025-2026 Tracker'!$K$2:$K$5000,'2025-2026 Tracker'!$A$2:$A$5000,">="&F3,'2025-2026 Tracker'!$A$2:$A$5000,"<="&EOMONTH(F3,0),'2025-2026 Tracker'!$B$2:$B$5000,"Expense",'2025-2026 Tracker'!$C$2:$C$5000,"Infrastructure/Hosting") -> 0 | G24: =SUMIFS('2025-2026 Tracker'!$K$2:$K$5000,'2025-2026 Tracker'!$A$2:$A$5000,">="&G3,'2025-2026 Tracker'!$A$2:$A$5000,"<="&EOMONTH(G3,0),'2025-2026 Tracker'!$B$2:$B$5000,"Expense",'2025-2026 Tracker'!$C$2:$C$5000,"Infrastructure/Hosting") -> 0 | H24: =SUMIFS('2025-2026 Tracker'!$K$2:$K$5000,'2025-2026 Tracker'!$A$2:$A$5000,">="&H3,'2025-2026 Tracker'!$A$2:$A$5000,"<="&EOMONTH(H3,0),'2025-2026 Tracker'!$B$2:$B$5000,"Expense",'2025-2026 Tracker'!$C$2:$C$5000,"Infrastructure/Hosting") -> 0 | I24: =SUMIFS('2025-2026 Tracker'!$K$2:$K$5000,'2025-2026 Tracker'!$A$2:$A$5000,">="&I3,'2025-2026 Tracker'!$A$2:$A$5000,"<="&EOMONTH(I3,0),'2025-2026 Tracker'!$B$2:$B$5000,"Expense",'2025-2026 Tracker'!$C$2:$C$5000,"Infrastructure/Hosting") -> 0 | J24: =SUMIFS('2025-2026 Tracker'!$K$2:$K$5000,'2025-2026 Tracker'!$A$2:$A$5000,">="&J3,'2025-2026 Tracker'!$A$2:$A$5000,"<="&EOMONTH(J3,0),'2025-2026 Tracker'!$B$2:$B$5000,"Expense",'2025-2026 Tracker'!$C$2:$C$5000,"Infrastructure/Hosting") -> 0 | ... Z24: =SUMIFS('2025-2026 Tracker'!$K$2:$K$5000,'2025-2026 Tracker'!$A$2:$A$5000,">="&Z3,'2025-2026 Tracker'!$A$2:$A$5000,"<="&EOMONTH(Z3,0),'2025-2026 Tracker'!$B$2:$B$5000,"Expense",'2025-2026 Tracker'!$C$2:$C$5000,"Infrastructure/Hosting") -> 0 | AA24: =SUM(C24:Z24) -> 0
A25: Travel/Meetings | C25: =SUMIFS('2025-2026 Tracker'!$K$2:$K$5000,'2025-2026 Tracker'!$A$2:$A$5000,">="&C3,'2025-2026 Tracker'!$A$2:$A$5000,"<="&EOMONTH(C3,0),'2025-2026 Tracker'!$B$2:$B$5000,"Expense",'2025-2026 Tracker'!$C$2:$C$5000,"Travel & meetings") -> 0 | D25: =SUMIFS('2025-2026 Tracker'!$K$2:$K$5000,'2025-2026 Tracker'!$A$2:$A$5000,">="&D3,'2025-2026 Tracker'!$A$2:$A$5000,"<="&EOMONTH(D3,0),'2025-2026 Tracker'!$B$2:$B$5000,"Expense",'2025-2026 Tracker'!$C$2:$C$5000,"Travel & meetings") -> 0 | E25: =SUMIFS('2025-2026 Tracker'!$K$2:$K$5000,'2025-2026 Tracker'!$A$2:$A$5000,">="&E3,'2025-2026 Tracker'!$A$2:$A$5000,"<="&EOMONTH(E3,0),'2025-2026 Tracker'!$B$2:$B$5000,"Expense",'2025-2026 Tracker'!$C$2:$C$5000,"Travel & meetings") -> 0 | F25: =SUMIFS('2025-2026 Tracker'!$K$2:$K$5000,'2025-2026 Tracker'!$A$2:$A$5000,">="&F3,'2025-2026 Tracker'!$A$2:$A$5000,"<="&EOMONTH(F3,0),'2025-2026 Tracker'!$B$2:$B$5000,"Expense",'2025-2026 Tracker'!$C$2:$C$5000,"Travel & meetings") -> 0 | G25: =SUMIFS('2025-2026 Tracker'!$K$2:$K$5000,'2025-2026 Tracker'!$A$2:$A$5000,">="&G3,'2025-2026 Tracker'!$A$2:$A$5000,"<="&EOMONTH(G3,0),'2025-2026 Tracker'!$B$2:$B$5000,"Expense",'2025-2026 Tracker'!$C$2:$C$5000,"Travel & meetings") -> 0 | H25: =SUMIFS('2025-2026 Tracker'!$K$2:$K$5000,'2025-2026 Tracker'!$A$2:$A$5000,">="&H3,'2025-2026 Tracker'!$A$2:$A$5000,"<="&EOMONTH(H3,0),'2025-2026 Tracker'!$B$2:$B$5000,"Expense",'2025-2026 Tracker'!$C$2:$C$5000,"Travel & meetings") -> 0 | I25: =SUMIFS('2025-2026 Tracker'!$K$2:$K$5000,'2025-2026 Tracker'!$A$2:$A$5000,">="&I3,'2025-2026 Tracker'!$A$2:$A$5000,"<="&EOMONTH(I3,0),'2025-2026 Tracker'!$B$2:$B$5000,"Expense",'2025-2026 Tracker'!$C$2:$C$5000,"Travel & meetings") -> 0 | J25: =SUMIFS('2025-2026 Tracker'!$K$2:$K$5000,'2025-2026 Tracker'!$A$2:$A$5000,">="&J3,'2025-2026 Tracker'!$A$2:$A$5000,"<="&EOMONTH(J3,0),'2025-2026 Tracker'!$B$2:$B$5000,"Expense",'2025-2026 Tracker'!$C$2:$C$5000,"Travel & meetings") -> 0 | ... Z25: =SUMIFS('2025-2026 Tracker'!$K$2:$K$5000,'2025-2026 Tracker'!$A$2:$A$5000,">="&Z3,'2025-2026 Tracker'!$A$2:$A$5000,"<="&EOMONTH(Z3,0),'2025-2026 Tracker'!$B$2:$B$5000,"Expense",'2025-2026 Tracker'!$C$2:$C$5000,"Travel & meetings") -> 0 | AA25: =SUM(C25:Z25) -> 0
A26: Office supplies/Equipment | C26: =SUMIFS('2025-2026 Tracker'!$K$2:$K$5000,'2025-2026 Tracker'!$A$2:$A$5000,">="&C3,'2025-2026 Tracker'!$A$2:$A$5000,"<="&EOMONTH(C3,0),'2025-2026 Tracker'!$B$2:$B$5000,"Expense",'2025-2026 Tracker'!$C$2:$C$5000,"Office supplies & equipment") -> 0 | D26: =SUMIFS('2025-2026 Tracker'!$K$2:$K$5000,'2025-2026 Tracker'!$A$2:$A$5000,">="&D3,'2025-2026 Tracker'!$A$2:$A$5000,"<="&EOMONTH(D3,0),'2025-2026 Tracker'!$B$2:$B$5000,"Expense",'2025-2026 Tracker'!$C$2:$C$5000,"Office supplies & equipment") -> 0 | E26: =SUMIFS('2025-2026 Tracker'!$K$2:$K$5000,'2025-2026 Tracker'!$A$2:$A$5000,">="&E3,'2025-2026 Tracker'!$A$2:$A$5000,"<="&EOMONTH(E3,0),'2025-2026 Tracker'!$B$2:$B$5000,"Expense",'2025-2026 Tracker'!$C$2:$C$5000,"Office supplies & equipment") -> 0 | F26: =SUMIFS('2025-2026 Tracker'!$K$2:$K$5000,'2025-2026 Tracker'!$A$2:$A$5000,">="&F3,'2025-2026 Tracker'!$A$2:$A$5000,"<="&EOMONTH(F3,0),'2025-2026 Tracker'!$B$2:$B$5000,"Expense",'2025-2026 Tracker'!$C$2:$C$5000,"Office supplies & equipment") -> 0 | G26: =SUMIFS('2025-2026 Tracker'!$K$2:$K$5000,'2025-2026 Tracker'!$A$2:$A$5000,">="&G3,'2025-2026 Tracker'!$A$2:$A$5000,"<="&EOMONTH(G3,0),'2025-2026 Tracker'!$B$2:$B$5000,"Expense",'2025-2026 Tracker'!$C$2:$C$5000,"Office supplies & equipment") -> 0 | H26: =SUMIFS('2025-2026 Tracker'!$K$2:$K$5000,'2025-2026 Tracker'!$A$2:$A$5000,">="&H3,'2025-2026 Tracker'!$A$2:$A$5000,"<="&EOMONTH(H3,0),'2025-2026 Tracker'!$B$2:$B$5000,"Expense",'2025-2026 Tracker'!$C$2:$C$5000,"Office supplies & equipment") -> 0 | I26: =SUMIFS('2025-2026 Tracker'!$K$2:$K$5000,'2025-2026 Tracker'!$A$2:$A$5000,">="&I3,'2025-2026 Tracker'!$A$2:$A$5000,"<="&EOMONTH(I3,0),'2025-2026 Tracker'!$B$2:$B$5000,"Expense",'2025-2026 Tracker'!$C$2:$C$5000,"Office supplies & equipment") -> 0 | J26: =SUMIFS('2025-2026 Tracker'!$K$2:$K$5000,'2025-2026 Tracker'!$A$2:$A$5000,">="&J3,'2025-2026 Tracker'!$A$2:$A$5000,"<="&EOMONTH(J3,0),'2025-2026 Tracker'!$B$2:$B$5000,"Expense",'2025-2026 Tracker'!$C$2:$C$5000,"Office supplies & equipment") -> 0 | ... Z26: =SUMIFS('2025-2026 Tracker'!$K$2:$K$5000,'2025-2026 Tracker'!$A$2:$A$5000,">="&Z3,'2025-2026 Tracker'!$A$2:$A$5000,"<="&EOMONTH(Z3,0),'2025-2026 Tracker'!$B$2:$B$5000,"Expense",'2025-2026 Tracker'!$C$2:$C$5000,"Office supplies & equipment") -> 0 | AA26: =SUM(C26:Z26) -> 0
A27: Other operational costs | C27: =SUMIFS('2025-2026 Tracker'!$K$2:$K$5000,'2025-2026 Tracker'!$A$2:$A$5000,">="&C3,'2025-2026 Tracker'!$A$2:$A$5000,"<="&EOMONTH(C3,0),'2025-2026 Tracker'!$B$2:$B$5000,"Expense",'2025-2026 Tracker'!$C$2:$C$5000,"Other operational costs") -> 0 | D27: =SUMIFS('2025-2026 Tracker'!$K$2:$K$5000,'2025-2026 Tracker'!$A$2:$A$5000,">="&D3,'2025-2026 Tracker'!$A$2:$A$5000,"<="&EOMONTH(D3,0),'2025-2026 Tracker'!$B$2:$B$5000,"Expense",'2025-2026 Tracker'!$C$2:$C$5000,"Other operational costs") -> 0 | E27: =SUMIFS('2025-2026 Tracker'!$K$2:$K$5000,'2025-2026 Tracker'!$A$2:$A$5000,">="&E3,'2025-2026 Tracker'!$A$2:$A$5000,"<="&EOMONTH(E3,0),'2025-2026 Tracker'!$B$2:$B$5000,"Expense",'2025-2026 Tracker'!$C$2:$C$5000,"Other operational costs") -> 0 | F27: =SUMIFS('2025-2026 Tracker'!$K$2:$K$5000,'2025-2026 Tracker'!$A$2:$A$5000,">="&F3,'2025-2026 Tracker'!$A$2:$A$5000,"<="&EOMONTH(F3,0),'2025-2026 Tracker'!$B$2:$B$5000,"Expense",'2025-2026 Tracker'!$C$2:$C$5000,"Other operational costs") -> 0 | G27: =SUMIFS('2025-2026 Tracker'!$K$2:$K$5000,'2025-2026 Tracker'!$A$2:$A$5000,">="&G3,'2025-2026 Tracker'!$A$2:$A$5000,"<="&EOMONTH(G3,0),'2025-2026 Tracker'!$B$2:$B$5000,"Expense",'2025-2026 Tracker'!$C$2:$C$5000,"Other operational costs") -> 0 | H27: =SUMIFS('2025-2026 Tracker'!$K$2:$K$5000,'2025-2026 Tracker'!$A$2:$A$5000,">="&H3,'2025-2026 Tracker'!$A$2:$A$5000,"<="&EOMONTH(H3,0),'2025-2026 Tracker'!$B$2:$B$5000,"Expense",'2025-2026 Tracker'!$C$2:$C$5000,"Other operational costs") -> 0 | I27: =SUMIFS('2025-2026 Tracker'!$K$2:$K$5000,'2025-2026 Tracker'!$A$2:$A$5000,">="&I3,'2025-2026 Tracker'!$A$2:$A$5000,"<="&EOMONTH(I3,0),'2025-2026 Tracker'!$B$2:$B$5000,"Expense",'2025-2026 Tracker'!$C$2:$C$5000,"Other operational costs") -> 0 | J27: =SUMIFS('2025-2026 Tracker'!$K$2:$K$5000,'2025-2026 Tracker'!$A$2:$A$5000,">="&J3,'2025-2026 Tracker'!$A$2:$A$5000,"<="&EOMONTH(J3,0),'2025-2026 Tracker'!$B$2:$B$5000,"Expense",'2025-2026 Tracker'!$C$2:$C$5000,"Other operational costs") -> 0 | ... Z27: =SUMIFS('2025-2026 Tracker'!$K$2:$K$5000,'2025-2026 Tracker'!$A$2:$A$5000,">="&Z3,'2025-2026 Tracker'!$A$2:$A$5000,"<="&EOMONTH(Z3,0),'2025-2026 Tracker'!$B$2:$B$5000,"Expense",'2025-2026 Tracker'!$C$2:$C$5000,"Other operational costs") -> 0 | AA27: =SUM(C27:Z27) -> 0
A29: Net Cash Flow | C29: =C4-C11 -> -13.92 | D29: =D4-D11 -> -59.6 | E29: =E4-E11 -> -13.92 | F29: =F4-F11 -> -13.92 | G29: =G4-G11 -> -13.92 | H29: =H4-H11 -> -13.92 | I29: =I4-I11 -> -13.92 | J29: =J4-J11 -> -13.92 | ... N29: =N4-N11 -> -13.92 | AA29: =SUM(C29:Z29) -> -212.72
A31: Starting Balance | D31: =C33 -> -13.92 | E31: =D33 -> -73.52 | F31: =E33 -> -87.44 | G31: =F33 -> -101.36 | H31: =G33 -> -115.28 | I31: =H33 -> -129.2 | J31: =I33 -> -143.12 | K31: =J33 -> -157.04 | ... N31: =M33 -> -198.8 | AA31: =SUM(C31:Z31) -> -1375.52
A32: Net Cash Flow | C32: =C29 -> -13.92 | D32: =D29 -> -59.6 | E32: =E29 -> -13.92 | F32: =F29 -> -13.92 | G32: =G29 -> -13.92 | H32: =H29 -> -13.92 | I32: =I29 -> -13.92 | J32: =J29 -> -13.92 | ... N32: =N29 -> -13.92 | AA32: =SUM(C32:Z32) -> -212.72
A33: Ending Cash Balance | C33: =C31+C32 -> -13.92 | D33: =D31+D32 -> -73.52 | E33: =E31+E32 -> -87.44 | F33: =F31+F32 -> -101.36 | G33: =G31+G32 -> -115.28 | H33: =H31+H32 -> -129.2 | I33: =I31+I32 -> -143.12 | J33: =J31+J32 -> -157.04 | ... N33: =N31+N32 -> -212.72 | AA33: =SUM(C33:Z33) -> -1588.24

Sheet 2023-2024 Tracker
A1: Date | B1: Type | C1: Category | D1: Subcategory | E1: Project | F1: Counterparty | G1: Description | H1: Amount (orig) | I1: Currency | J1: FX rate (to EUR) | K1: Amount (EUR) | L1: Payment method | M1: Status | N1: Paid by | O1: Reimbursement status | P1: Receipt / doc ref | Q1: Invoice # | R1: Notes | S1: Estimated?
A2: 45164 | B2: Expense | C2: Fixed costs | D2: Obsidian Publish | E2: ReFi BCN Website maintenance | F2: Obsidian | G2: Obsidian Publish subscription (monthly) | H2: 10 | I2: USD | J2: =IFERROR(__xludf.DUMMYFUNCTION("IFERROR(INDEX(GOOGLEFINANCE(""CURRENCY:USDEUR"",A2),2,2),"""")"),"") | K2: =IFERROR(H2*J2,"") -> 0 | L2: Card | M2: Cleared | N2: Luiz personal | O2: To be reimbursed | R2: Amount paid: 10 USD (convert to EUR when known). Ongoing, not settled (reimbursement pending). | S2: No
A3: 45195 | B3: Expense | C3: Fixed costs | D3: Obsidian Publish | E3: ReFi BCN Website maintenance | F3: Obsidian | G3: Obsidian Publish subscription (monthly) | H3: 10 | I3: USD | J3: =IFERROR(__xludf.DUMMYFUNCTION("IFERROR(INDEX(GOOGLEFINANCE(""CURRENCY:USDEUR"",A3),2,2),"""")"),"") | K3: =IFERROR(H3*J3,"") -> 0 | L3: Card | M3: Cleared | N3: Luiz personal | O3: To be reimbursed | R3: Amount paid: 10 USD (convert to EUR when known). Ongoing, not settled (reimbursement pending). | S3: No
A4: 45225 | B4: Expense | C4: Fixed costs | D4: Obsidian Publish | E4: ReFi BCN Website maintenance | F4: Obsidian | G4: Obsidian Publish subscription (monthly) | H4: 10 | I4: USD | J4: =IFERROR(__xludf.DUMMYFUNCTION("IFERROR(INDEX(GOOGLEFINANCE(""CURRENCY:USDEUR"",A4),2,2),"""")"),"") | K4: =IFERROR(H4*J4,"") -> 0 | L4: Card | M4: Cleared | N4: Luiz personal | O4: To be reimbursed | R4: Amount paid: 10 USD (convert to EUR when known). Ongoing, not settled (reimbursement pending). | S4: No
A5: 45256 | B5: Expense | C5: Fixed costs | D5: Obsidian Publish | E5: ReFi BCN Website maintenance | F5: Obsidian | G5: Obsidian Publish subscription (monthly) | H5: 10 | I5: USD | J5: =IFERROR(__xludf.DUMMYFUNCTION("IFERROR(INDEX(GOOGLEFINANCE(""CURRENCY:USDEUR"",A5),2,2),"""")"),"") | K5: =IFERROR(H5*J5,"") -> 0 | L5: Card | M5: Cleared | N5: Luiz personal | O5: To be reimbursed | R5: Amount paid: 10 USD (convert to EUR when known). Ongoing, not settled (reimbursement pending). | S5: No
A6: 45286 | B6: Expense | C6: Fixed costs | D6: Obsidian Publish | E6: ReFi BCN Website maintenance | F6: Obsidian | G6: Obsidian Publish subscription (monthly) | H6: 10 | I6: USD | J6: =IFERROR(__xludf.DUMMYFUNCTION("IFERROR(INDEX(GOOGLEFINANCE(""CURRENCY:USDEUR"",A6),2,2),"""")"),"") | K6: =IFERROR(H6*J6,"") -> 0 | L6: Card | M6: Cleared | N6: Luiz personal | O6: To be reimbursed | R6: Amount paid: 10 USD (convert to EUR when known). Ongoing, not settled (reimbursement pending). | S6: No
A7: 45317 | B7: Expense | C7: Fixed costs | D7: Obsidian Publish | E7: ReFi BCN Website maintenance | F7: Obsidian | G7: Obsidian Publish subscription (monthly) | H7: 10 | I7: USD | J7: =IFERROR(__xludf.DUMMYFUNCTION("IFERROR(INDEX(GOOGLEFINANCE(""CURRENCY:USDEUR"",A7),2,2),"""")"),"") | K7: =IFERROR(H7*J7,"") -> 0 | L7: Card | M7: Cleared | N7: Luiz personal | O7: To be reimbursed | R7: Amount paid: 10 USD (convert to EUR when known). Ongoing, not settled (reimbursement pending). | S7: No
A8: 45348 | B8: Expense | C8: Fixed costs | D8: Obsidian Publish | E8: ReFi BCN Website maintenance | F8: Obsidian | G8: Obsidian Publish subscription (monthly) | H8: 10 | I8: USD | J8: =IFERROR(__xludf.DUMMYFUNCTION("IFERROR(INDEX(GOOGLEFINANCE(""CURRENCY:USDEUR"",A8),2,2),"""")"),"") | K8: =IFERROR(H8*J8,"") -> 0 | L8: Card | M8: Cleared | N8: Luiz personal | O8: To be reimbursed | R8: Amount paid: 10 USD (convert to EUR when known). Ongoing, not settled (reimbursement pending). | S8: No
A9: 45377 | B9: Expense | C9: Fixed costs | D9: Obsidian Publish | E9: ReFi BCN Website maintenance | F9: Obsidian | G9: Obsidian Publish subscription (monthly) | H9: 10 | I9: USD | J9: =IFERROR(__xludf.DUMMYFUNCTION("IFERROR(INDEX(GOOGLEFINANCE(""CURRENCY:USDEUR"",A9),2,2),"""")"),"") | K9: =IFERROR(H9*J9,"") -> 0 | L9: Card | M9: Cleared | N9: Luiz personal | O9: To be reimbursed | R9: Amount paid: 10 USD (convert to EUR when known). Ongoing, not settled (reimbursement pending). | S9: No
A10: 45408 | B10: Expense | C10: Fixed costs | D10: Obsidian Publish | E10: ReFi BCN Website maintenance | F10: Obsidian | G10: Obsidian Publish subscription (monthly) | H10: 10 | I10: USD | J10: =IFERROR(__xludf.DUMMYFUNCTION("IFERROR(INDEX(GOOGLEFINANCE(""CURRENCY:USDEUR"",A10),2,2),"""")"),"") | K10: =IFERROR(H10*J10,"") -> 0 | L10: Card | M10: Cleared | N10: Luiz personal | O10: To be reimbursed | R10: Amount paid: 10 USD (convert to EUR when known). Ongoing, not settled (reimbursement pending). | S10: No
A11: 45438 | B11: Expense | C11: Fixed costs | D11: Obsidian Publish | E11: ReFi BCN Website maintenance | F11: Obsidian | G11: Obsidian Publish subscription (monthly) | H11: 10 | I11: USD | J11: =IFERROR(__xludf.DUMMYFUNCTION("IFERROR(INDEX(GOOGLEFINANCE(""CURRENCY:USDEUR"",A11),2,2),"""")"),"") | K11: =IFERROR(H11*J11,"") -> 0 | L11: Card | M11: Cleared | N11: Luiz personal | O11: To be reimbursed | R11: Amount paid: 10 USD (convert to EUR when known). Ongoing, not settled (reimbursement pending). | S11: No
A12: 45469 | B12: Expense | C12: Fixed costs | D12: Obsidian Publish | E12: ReFi BCN Website maintenance | F12: Obsidian | G12: Obsidian Publish subscription (monthly) | H12: 10 | I12: USD | J12: =IFERROR(__xludf.DUMMYFUNCTION("IFERROR(INDEX(GOOGLEFINANCE(""CURRENCY:USDEUR"",A12),2,2),"""")"),"") | K12: =IFERROR(H12*J12,"") -> 0 | L12: Card | M12: Cleared | N12: Luiz personal | O12: To be reimbursed | R12: Amount paid: 10 USD (convert to EUR when known). Ongoing, not settled (reimbursement pending). | S12: No
